Workbook

Sheet Feb 2025
A1: Oriental University, Indore
A2: Faculty of Computer Science & Engineering
A3: B. Tech(Plain) - A Section , II Semester Attendance:Apr 2025
A4: S.No. | B4: Enrolment No. | C4: Name of Student | D4: Engineering Mathematics-II ENXX3BS03 | E4: Fundamentals of Engineering ENXX3ES02 | F4: Communication Skills-II ENXX3HS03P | G4: Programming in C CSXX3CO17 | H4: Digital Systems CSXX3ES02 | I4: Universal Human Values ENXX3HS04 | J4: Life Skill Tool Kit ENXX3SE02 | K4: Total Class | L4: Percentage
K7: =SUM(D7:J7) -> 0 | L7: %
D8: 10 | E8: 9 | F8: 2 | G8: 6 | H8: 7 | I8: 4 | J8: 2 | K8: =SUM(D8:J8) -> 40
A9: 1 | B9: 2425CS8383 | C9: Aanchal Pandey | D9: 0 | E9: 2 | F9: 0 | G9: 2 | H9: 1 | I9: 1 | J9: 2 | K9: =SUM(D9:J9) -> 8 | L9: =(K9/K8) -> 0.2
A10: 2 | B10: 243CA0063 | C10: Aastha Mathankar | D10: 3 | E10: 0 | F10: 2 | G10: 0 | H10: 0 | I10: 0 | J10: 1 | K10: =SUM(D10:J10) -> 6 | L10: =(K10/K8) -> 0.15
A11: 3 | B11: 243CS0118 | C11: Abhiman Maurya | D11: 2 | E11: 0 | F11: 2 | G11: 0 | H11: 0 | I11: 0 | J11: 2 | K11: =SUM(D11:J11) -> 6 | L11: =(K11/K8) -> 0.15
A12: 4 | B12: 243CS0110 | C12: Abhishek Patidar | D12: 0 | E12: 0 | F12: 0 | G12: 0 | H12: 0 | I12: 0 | J12: 0 | K12: =SUM(D12:J12) -> 0 | L12: =(K12/K8) -> 0
A13: 5 | B13: 243CS0073 | C13: Aditya Barsena | D13: 4 | E13: 4 | F13: 0 | G13: 5 | H13: 6 | I13: 1 | J13: 1 | K13: =SUM(D13:J13) -> 21 | L13: =(K13/K8) -> 0.525
A14: 6 | B14: 243CSD003 | C14: Aditya Dev Pandey | D14: 4 | E14: 0 | F14: 0 | G14: 0 | H14: 0 | I14: 0 | J14: 1 | K14: =SUM(D14:J14) -> 5 | L14: =(K14/K8) -> 0.125
A15: 7 | B15: 243CS0053 | C15: Ankit Dabi | D15: 7 | E15: 2 | F15: 0 | G15: 0 | H15: 0 | I15: 1 | J15: 1 | K15: =SUM(D15:J15) -> 11 | L15: =(K15/K8) -> 0.275
A16: 8 | B16: 243CS0026 | C16: Arman Chandravanshi | D16: 7 | E16: 4 | F16: 0 | G16: 5 | H16: 6 | I16: 3 | J16: 0 | K16: =SUM(D16:J16) -> 25 | L16: =(K16/K8) -> 0.625
A17: 9 | B17: 243CS0025 | C17: Ayush Chourey | D17: 5 | E17: 0 | F17: 0 | G17: 0 | H17: 0 | I17: 0 | J17: 1 | K17: =SUM(D17:J17) -> 6 | L17: =(K17/K8) -> 0.15
A18: 10 | B18: 243CS0004 | C18: Ayush Kumar Sinha | D18: 2 | E18: 0 | F18: 0 | G18: 0 | H18: 0 | I18: 0 | J18: 0 | K18: =SUM(D18:J18) -> 2 | L18: =(K18/K8) -> 0.05
A19: 11 | B19: 243CS0165 | C19: Bhumika Kale | D19: 8 | E19: 4 | F19: 2 | G19: 5 | H19: 5 | I19: 1 | J19: 0 | K19: =SUM(D19:J19) -> 25 | L19: =(K19/K8) -> 0.625
A20: 12 | B20: 243CS0047 | C20: Chandani Kose | D20: 9 | E20: 4 | F20: 2 | G20: 5 | H20: 4 | I20: 1 | J20: 1 | K20: =SUM(D20:J20) -> 26 | L20: =(K20/K8) -> 0.65
A21: 13 | B21: 243CS0065 | C21: Daksh Mandiwal | D21: 9 | E21: 3 | F21: 2 | G21: 5 | H21: 5 | I21: 1 | J21: 0 | K21: =SUM(D21:J21) -> 25 | L21: =(K21/K8) -> 0.625
A22: 14 | B22: 243CS0159 | C22: Dakshita Shukla | D22: 8 | E22: 4 | F22: 2 | G22: 5 | H22: 5 | I22: 2 | J22: 0 | K22: =SUM(D22:J22) -> 26 | L22: =(K22/K8) -> 0.65
A23: 15 | B23: 243CS0034 | C23: Dhananjay Vishwakarma | D23: 0 | E23: 0 | F23: 0 | G23: 0 | H23: 0 | I23: 0 | J23: 0 | K23: =SUM(D23:J23) -> 0 | L23: =(K23/K8) -> 0
A24: 16 | B24: 243CS0045 | C24: Gautam Kumar Mishra | D24: 0 | E24: 0 | F24: 0 | G24: 0 | H24: 0 | I24: 0 | J24: 0 | K24: =SUM(D24:J24) -> 0 | L24: =(K24/K8) -> 0
A25: 17 | B25: 243CS0018 | C25: Gouri Rathod | D25: 4 | E25: 0 | F25: 0 | G25: 0 | H25: 0 | I25: 0 | J25: 0 | K25: =SUM(D25:J25) -> 4 | L25: =(K25/K8) -> 0.1
A26: 18 | B26: 243CS0019 | C26: Gungun Kumari | D26: 5 | E26: 2 | F26: 0 | G26: 3 | H26: 3 | I26: 2 | J26: 0 | K26: =SUM(D26:J26) -> 15 | L26: =(K26/K8) -> 0.375
A27: 19 | B27: 243CA0014 | C27: Hariom Jadoun | D27: 6 | E27: 0 | F27: 2 | G27: 0 | H27: 0 | I27: 0 | J27: 0 | K27: =SUM(D27:J27) -> 8 | L27: =(K27/K8) -> 0.2
A28: 20 | B28: 243CSA067 | C28: Hariom Parmar | D28: 7 | E28: 3 | F28: 0 | G28: 3 | H28: 0 | I28: 0 | J28: 0 | K28: =SUM(D28:J28) -> 13 | L28: =(K28/K8) -> 0.325
A29: 21 | B29: 243CS0137 | C29: Kailash Nandeda | D29: 7 | E29: 1 | F29: 0 | G29: 2 | H29: 2 | I29: 1 | J29: 0 | K29: =SUM(D29:J29) -> 13 | L29: =(K29/K8) -> 0.325
A30: 22 | B30: 243CS0006 | C30: Kartik Maurya | D30: 6 | E30: 2 | F30: 0 | G30: 3 | H30: 2 | I30: 0 | J30: 1 | K30: =SUM(D30:J30) -> 14 | L30: =(K30/K8) -> 0.35
A31: 23 | B31: 243CS0079 | C31: Kore Shiva Kumar | D31: 0 | E31: 0 | F31: 0 | G31: 0 | H31: 0 | I31: 0 | J31: 0 | K31: =SUM(D31:J31) -> 0 | L31: =(K31/K8) -> 0
A32: 24 | B32: 243CS0116 | C32: Kunal Kumawat | D32: 8 | E32: 3 | F32: 2 | G32: 4 | H32: 3 | I32: 2 | J32: 0 | K32: =SUM(D32:J32) -> 22 | L32: =(K32/K8) -> 0.55
A33: 25 | B33: 243CS0141 | C33: Kushagra Purohit | D33: 0 | E33: 0 | F33: 0 | G33: 0 | H33: 0 | I33: 0 | J33: 0 | K33: =SUM(D33:J33) -> 0 | L33: =(K33/K8) -> 0
A34: 26 | B34: 243CSA160 | C34: Lakshay | D34: 2 | E34: 1 | F34: 2 | G34: 0 | H34: 0 | I34: 0 | J34: 0 | K34: =SUM(D34:J34) -> 5 | L34: =(K34/K8) -> 0.125
A35: 27 | B35: 243CS0154 | C35: Larvia Nankani | D35: 8 | E35: 3 | F35: 2 | G35: 5 | H35: 3 | I35: 1 | J35: 0 | K35: =SUM(D35:J35) -> 22 | L35: =(K35/K8) -> 0.55
A36: 28 | B36: 243CS0105 | C36: Manish Satpute | D36: 8 | E36: 1 | F36: 0 | G36: 0 | H36: 0 | I36: 0 | J36: 1 | K36: =SUM(D36:J36) -> 10 | L36: =(K36/K8) -> 0.25
A37: 29 | B37: 243CS0069 | C37: Manoj Chouhan | D37: 8 | E37: 0 | F37: 0 | G37: 0 | H37: 0 | I37: 0 | J37: 0 | K37: =SUM(D37:J37) -> 8 | L37: =(K37/K8) -> 0.2
A38: 30 | B38: 243CS0043 | C38: Minal Ratnawat | D38: 7 | E38: 1 | F38: 0 | G38: 1 | H38: 1 | I38: 0 | J38: 1 | K38: =SUM(D38:J38) -> 11 | L38: =(K38/K8) -> 0.275
A39: 31 | B39: 243CS0054 | C39: Mishra Shrayansh Mukesh | D39: 5 | E39: 2 | F39: 2 | G39: 2 | H39: 0 | I39: 2 | J39: 1 | K39: =SUM(D39:J39) -> 14 | L39: =(K39/K8) -> 0.35
A40: 32 | B40: 243CS0075 | C40: Muskan Pawar | D40: 6 | E40: 0 | F40: 0 | G40: 0 | H40: 0 | I40: 0 | J40: 1 | K40: =SUM(D40:J40) -> 7 | L40: =(K40/K8) -> 0.175
A41: 33 | B41: 243CSE021 | C41: Narendra | D41: 5 | E41: 0 | F41: 0 | G41: 0 | H41: 0 | I41: 1 | J41: 0 | K41: =SUM(D41:J41) -> 6 | L41: =(K41/K8) -> 0.15
A42: 34 | B42: 243CS0143 | C42: Neha Rathore | D42: 2 | E42: 0 | F42: 0 | G42: 0 | H42: 0 | I42: 0 | J42: 1 | K42: =SUM(D42:J42) -> 3 | L42: =(K42/K8) -> 0.075
...

Sheet March 2025
A1: Oriental University, Indore
A2: Faculty of Computer Science & Engineering
A3: B. Tech(Plain) - A Section , II Semester Attendance: March 2025
A4: S.No. | B4: Enrolment No. | C4: Name of Student | D4: Bootcamp | E4: Engineering Mathematics-II ENXX3BS03 | F4: Fundamentals of Engineering ENXX3ES02 | G4: Communication Skills-II ENXX3HS03P (Till 17/03/25) | H4: Programming in C CSXX3CO17 | I4: Digital Systems CSXX3ES02 | J4: Universal Human Values ENXX3HS04 | K4: Life Skill Tool Kit ENXX3SE02 | L4: Total Class | M4: Percentage | N4: Feb+March
L7: =SUM(E7:K7) -> 0 | M7: %
E8: 5 | F8: 9 | G8: 4 | H8: 5 | I8: 9 | J8: 10 | K8: 3 | L8: =SUM(E8:K8) -> 45 | N8: =L8+'Feb 2025'!K8 -> 85
A9: 1 | B9: 2425CS8383 | C9: Aanchal Pandey | D9: 5 | E9: 0 | F9: 1 | G9: 0 | H9: 0 | I9: 3 | J9: 2 | K9: 0 | L9: =SUM(D9:K9) -> 11 | M9: =(L9/L8)*100 -> 24.444444 | N9: =L9+'Feb 2025'!K9 -> 19 | O9: =N9/N8 -> 0.22352941
A10: 2 | B10: 243CA0063 | C10: Aastha Mathankar | D10: 7 | E10: 2 | F10: 3 | G10: 2 | H10: 0 | I10: 4 | J10: 2 | K10: 1 | L10: =SUM(D10:K10) -> 21 | M10: =(L10/L8)*100 -> 46.666667 | N10: =L10+'Feb 2025'!K10 -> 27 | O10: =N10/N8 -> 0.31764706
A11: 3 | B11: 243CS0118 | C11: Abhiman Maurya | D11: 0 | E11: 1 | F11: 3 | G11: 0 | H11: 3 | I11: 5 | J11: 4 | K11: 3 | L11: =SUM(D11:K11) -> 19 | M11: =(L11/L8)*100 -> 42.222222 | N11: =L11+'Feb 2025'!K11 -> 25 | O11: =N11/N8 -> 0.29411765
A12: 4 | B12: 243CS0110 | C12: Abhishek Patidar | D12: 0 | E12: 0 | F12: 0 | G12: 0 | H12: 0 | I12: 0 | J12: 0 | K12: 0 | L12: =SUM(D12:K12) -> 0 | M12: =(L12/L8)*100 -> 0 | N12: =L12+'Feb 2025'!K12 -> 0 | O12: =M12/N8 -> 0
A13: 5 | B13: 243CS0073 | C13: Aditya Barsena | D13: 0 | E13: 2 | F13: 6 | G13: 0 | H13: 4 | I13: 6 | J13: 2 | K13: 1 | L13: =SUM(D13:K13) -> 21 | M13: =(L13/L8)*100 -> 46.666667 | N13: =L13+'Feb 2025'!K13 -> 42 | O13: =M13/N8 -> 0.54901961
A14: 6 | B14: 243CSD003 | C14: Aditya Dev Pandey | D14: 0 | E14: 1 | F14: 0 | G14: 0 | H14: 0 | I14: 4 | J14: 0 | K14: 1 | L14: =SUM(D14:K14) -> 6 | M14: =(L14/L8)*100 -> 13.333333 | N14: =L14+'Feb 2025'!K14 -> 11 | O14: =M14/N8 -> 0.15686275
A15: 7 | B15: 243CS0053 | C15: Ankit Dabi | D15: 0 | E15: 4 | F15: 4 | G15: 0 | H15: 2 | I15: 5 | J15: 4 | K15: 2 | L15: =SUM(D15:K15) -> 21 | M15: =(L15/L8)*100 -> 46.666667 | N15: =L15+'Feb 2025'!K15 -> 32 | O15: =N15/N8 -> 0.37647059
A16: 8 | B16: 243CS0026 | C16: Arman Chandravanshi | D16: 7 | E16: 3 | F16: 2 | G16: 2 | H16: 2 | I16: 5 | J16: 8 | K16: 1 | L16: =SUM(D16:K16) -> 30 | M16: =(L16/L8)*100 -> 66.666667 | N16: =L16+'Feb 2025'!K16 -> 55 | O16: =N16/N8 -> 0.64705882
A17: 9 | B17: 243CS0025 | C17: Ayush Chourey | D17: 0 | E17: 4 | F17: 3 | G17: 0 | H17: 4 | I17: 2 | J17: 4 | K17: 1 | L17: =SUM(D17:K17) -> 18 | M17: =(L17/L8)*100 -> 40 | N17: =L17+'Feb 2025'!K17 -> 24 | O17: =N17/N8 -> 0.28235294
A18: 10 | B18: 243CS0004 | C18: Ayush Kumar Sinha | D18: 7 | E18: 1 | F18: 0 | G18: 0 | H18: 0 | I18: 0 | J18: 0 | K18: 0 | L18: =SUM(D18:K18) -> 8 | M18: =(L18/L8)*100 -> 17.777778 | N18: =L18+'Feb 2025'!K18 -> 10 | O18: =N18/N8 -> 0.11764706
A19: 11 | B19: 243CS0165 | C19: Bhumika Kale | D19: 0 | E19: 3 | F19: 3 | G19: 0 | H19: 2 | I19: 6 | J19: 0 | K19: 0 | L19: =SUM(D19:K19) -> 14 | M19: =(L19/L8)*100 -> 31.111111 | N19: =L19+'Feb 2025'!K19 -> 39 | O19: =N19/N8 -> 0.45882353
A20: 12 | B20: 243CS0047 | C20: Chandani Kose | D20: 7 | E20: 3 | F20: 2 | G20: 2 | H20: 2 | I20: 6 | J20: 4 | K20: 1 | L20: =SUM(D20:K20) -> 27 | M20: =(L20/L8)*100 -> 60 | N20: =L20+'Feb 2025'!K20 -> 53 | O20: =N20/N8 -> 0.62352941
A21: 13 | B21: 243CS0065 | C21: Daksh Mandiwal | D21: 0 | E21: 3 | F21: 3 | G21: 0 | H21: 3 | I21: 6 | J21: 2 | K21: 0 | L21: =SUM(D21:K21) -> 17 | M21: =(L21/L8)*100 -> 37.777778 | N21: =L21+'Feb 2025'!K21 -> 42 | O21: =N21/N8 -> 0.49411765
A22: 14 | B22: 243CS0159 | C22: Dakshita Shukla | D22: 0 | E22: 4 | F22: 4 | G22: 0 | H22: 4 | I22: 6 | J22: 4 | K22: 0 | L22: =SUM(D22:K22) -> 22 | M22: =(L22/L8)*100 -> 48.888889 | N22: =L22+'Feb 2025'!K22 -> 48 | O22: =N22/N8 -> 0.56470588
A23: 15 | B23: 243CS0034 | C23: Dhananjay Vishwakarma | D23: 0 | E23: 0 | F23: 0 | G23: 0 | H23: 0 | I23: 0 | J23: 0 | K23: 0 | L23: =SUM(D23:K23) -> 0 | M23: =(L23/L8)*100 -> 0 | N23: =L23+'Feb 2025'!K23 -> 0 | O23: =N23/N8 -> 0
A24: 16 | B24: 243CS0045 | C24: Gautam Kumar Mishra | D24: 0 | E24: 0 | F24: 0 | G24: 0 | H24: 0 | I24: 2 | J24: 0 | K24: 0 | L24: =SUM(D24:K24) -> 2 | M24: =(L24/L8)*100 -> 4.4444444 | N24: =L24+'Feb 2025'!K24 -> 2 | O24: =N24/N8 -> 0.023529412
A25: 17 | B25: 243CS0018 | C25: Gouri Rathod | D25: 0 | E25: 1 | F25: 3 | G25: 0 | H25: 3 | I25: 4 | J25: 0 | K25: 0 | L25: =SUM(D25:K25) -> 11 | M25: =(L25/L8)*100 -> 24.444444 | N25: =L25+'Feb 2025'!K25 -> 15 | O25: =N25/N8 -> 0.17647059
A26: 18 | B26: 243CS0019 | C26: Gungun Kumari | D26: 0 | E26: 3 | F26: 6 | G26: 0 | H26: 3 | I26: 6 | J26: 3 | K26: 2 | L26: =SUM(D26:K26) -> 23 | M26: =(L26/L8)*100 -> 51.111111 | N26: =L26+'Feb 2025'!K26 -> 38 | O26: =N26/N8 -> 0.44705882
A27: 19 | B27: 243CA0014 | C27: Hariom Jadoun | D27: 0 | E27: 3 | F27: 4 | G27: 0 | H27: 2 | I27: 5 | J27: 3 | K27: 3 | L27: =SUM(D27:K27) -> 20 | M27: =(L27/L8)*100 -> 44.444444 | N27: =L27+'Feb 2025'!K27 -> 28 | O27: =N27/N8 -> 0.32941176
A28: 20 | B28: 243CSA067 | C28: Hariom Parmar | D28: 0 | E28: 5 | F28: 6 | G28: 0 | H28: 4 | I28: 5 | J28: 4 | K28: 3 | L28: =SUM(D28:K28) -> 27 | M28: =(L28/L8)*100 -> 60 | N28: =L28+'Feb 2025'!K28 -> 40 | O28: =N28/N8 -> 0.47058824
A29: 21 | B29: 243CS0137 | C29: Kailash Nandeda | D29: 0 | E29: 2 | F29: 3 | G29: 0 | H29: 0 | I29: 6 | J29: 3 | K29: 0 | L29: =SUM(D29:K29) -> 14 | M29: =(L29/L8)*100 -> 31.111111 | N29: =L29+'Feb 2025'!K29 -> 27 | O29: =N29/N8 -> 0.31764706
A30: 22 | B30: 243CS0006 | C30: Kartik Maurya | D30: 7 | E30: 4 | F30: 4 | G30: 2 | H30: 2 | I30: 5 | J30: 3 | K30: 1 | L30: =SUM(D30:K30) -> 28 | M30: =(L30/L8)*100 -> 62.222222 | N30: =L30+'Feb 2025'!K30 -> 42 | O30: =N30/N8 -> 0.49411765
A31: 23 | B31: 243CS0079 | C31: Kore Shiva Kumar | D31: 0 | E31: 0 | F31: 0 | G31: 0 | H31: 0 | I31: 0 | J31: 0 | K31: 0 | L31: =SUM(D31:K31) -> 0 | M31: =(L31/L8)*100 -> 0 | N31: =L31+'Feb 2025'!K31 -> 0 | O31: =N31/N8 -> 0
A32: 24 | B32: 243CS0116 | C32: Kunal Kumawat | D32: 7 | E32: 4 | F32: 5 | G32: 2 | H32: 0 | I32: 6 | J32: 6 | K32: 3 | L32: =SUM(D32:K32) -> 33 | M32: =(L32/L8)*100 -> 73.333333 | N32: =L32+'Feb 2025'!K32 -> 55 | O32: =N32/N8 -> 0.64705882
A33: 25 | B33: 243CS0141 | C33: Kushagra Purohit | D33: 0 | E33: 0 | F33: 0 | G33: 0 | H33: 0 | I33: 0 | J33: 0 | K33: 1 | L33: =SUM(D33:K33) -> 1 | M33: =(L33/L8)*100 -> 2.2222222 | N33: =L33+'Feb 2025'!K33 -> 1 | O33: =N33/N8 -> 0.011764706
A34: 26 | B34: 243CSA160 | C34: Lakshay | D34: 7 | E34: 1 | F34: 1 | G34: 0 | H34: 0 | I34: 4 | J34: 2 | K34: 0 | L34: =SUM(D34:K34) -> 15 | M34: =(L34/L8)*100 -> 33.333333 | N34: =L34+'Feb 2025'!K34 -> 20 | O34: =N34/N8 -> 0.23529412
A35: 27 | B35: 243CS0154 | C35: Larvia Nankani | D35: 7 | E35: 3 | F35: 0 | G35: 2 | H35: 0 | I35: 4 | J35: 5 | K35: 0 | L35: =SUM(D35:K35) -> 21 | M35: =(L35/L8)*100 -> 46.666667 | N35: =L35+'Feb 2025'!K35 -> 43 | O35: =N35/N8 -> 0.50588235
A36: 28 | B36: 243CS0105 | C36: Manish Satpute | D36: 0 | E36: 3 | F36: 2 | G36: 0 | H36: 2 | I36: 4 | J36: 3 | K36: 1 | L36: =SUM(D36:K36) -> 15 | M36: =(L36/L8)*100 -> 33.333333 | N36: =L36+'Feb 2025'!K36 -> 25 | O36: =N36/N8 -> 0.29411765
A37: 29 | B37: 243CS0069 | C37: Manoj Chouhan | D37: 7 | E37: 2 | F37: 2 | G37: 2 | H37: 0 | I37: 3 | J37: 2 | K37: 1 | L37: =SUM(D37:K37) -> 19 | M37: =(L37/L8)*100 -> 42.222222 | N37: =L37+'Feb 2025'!K37 -> 27 | O37: =N37/N8 -> 0.31764706
A38: 30 | B38: 243CS0043 | C38: Minal Ratnawat | D38: 7 | E38: 3 | F38: 4 | G38: 2 | H38: 2 | I38: 5 | J38: 3 | K38: 1 | L38: =SUM(D38:K38) -> 27 | M38: =(L38/L8)*100 -> 60 | N38: =L38+'Feb 2025'!K38 -> 38 | O38: =N38/N8 -> 0.44705882
A39: 31 | B39: 243CS0054 | C39: Mishra Shrayansh Mukesh | D39: 4 | E39: 2 | F39: 1 | G39: 0 | H39: 0 | I39: 3 | J39: 4 | K39: 1 | L39: =SUM(D39:K39) -> 15 | M39: =(L39/L8)*100 -> 33.333333 | N39: =L39+'Feb 2025'!K39 -> 29 | O39: =N39/N8 -> 0.34117647
A40: 32 | B40: 243CS0075 | C40: Muskan Pawar | D40: 7 | E40: 2 | F40: 2 | G40: 2 | H40: 0 | I40: 5 | J40: 3 | K40: 1 | L40: =SUM(D40:K40) -> 22 | M40: =(L40/L8)*100 -> 48.888889 | N40: =L40+'Feb 2025'!K40 -> 29 | O40: =N40/N8 -> 0.34117647
A41: 33 | B41: 243CSE021 | C41: Narendra | D41: 0 | E41: 0 | F41: 0 | G41: 0 | H41: 0 | I41: 0 | J41: 0 | K41: 0 | L41: =SUM(D41:K41) -> 0 | M41: =(L41/L8)*100 -> 0 | N41: =L41+'Feb 2025'!K41 -> 6 | O41: =N41/N8 -> 0.070588235
A42: 34 | B42: 243CS0143 | C42: Neha Rathore | D42: 4 | E42: 0 | F42: 1 | G42: 0 | H42: 0 | I42: 4 | J42: 3 | K42: 1 | L42: =SUM(D42:K42) -> 13 | M42: =(L42/L8)*100 -> 28.888889 | N42: =L42+'Feb 2025'!K42 -> 16 | O42: =N42/N8 -> 0.18823529
...

Sheet April 2025
A1: Oriental University, Indore
A2: Faculty of Computer Science & Engineering
A3: B. Tech(Plain) - A Section , II Semester Attendance: April 2025
A4: S.No. | B4: Enrolment No. | C4: Name of Student | D4: Engineering Mathematics-II ENXX3BS03 | E4: Fundamentals of Engineering ENXX3ES02 | F4: Fundamentals of Engineering ENXX3ES02 | G4: Communication Skills-II ENXX3HS03P 2 X 3 | H4: Programming in C CSXX3CO17 | I4: Digital Systems CSXX3ES02 | J4: Universal Human Values ENXX3HS04 | K4: Life Skill Tool Kit ENXX3SE02(4 Hrs) | L4: Total Class | M4: Percentage | N4: Total Class of feb+march+april | O4: Total Percentage of feb+march+april
L7: =SUM(D7:K7) -> 0 | M7: %
D8: 10 | E8: 10 | F8: 7 | G8: 6 | H8: 8 | I8: 10 | J8: 5 | K8: 2 | L8: =SUM(D8:K8) -> 58 | N8: =L8+'March 2025'!L8+'Feb 2025'!K8 -> 143
A9: 1 | B9: 2425CS8383 | C9: Aanchal Pandey | D9: 2 | E9: 3 | F9: 0 | G9: 2 | H9: 0 | I9: 2 | J9: 1 | K9: 0 | L9: =SUM(D9:K9) -> 10 | M9: =(L9/56)*100 -> 17.857143 | N9: =L9+'March 2025'!L9+'Feb 2025'!K9 -> 29 | O9: =N9/143 -> 0.2027972
A10: 2 | B10: 243CA0063 | C10: Aastha Mathankar | D10: 5 | E10: 6 | F10: 3 | G10: 0 | H10: 4 | I10: 5 | J10: 1 | K10: 0 | L10: =SUM(D10:K10) -> 24 | M10: =(L10/56)*100 -> 42.857143 | N10: =L10+'March 2025'!L10+'Feb 2025'!K10 -> 51 | O10: =N10/143 -> 0.35664336
A11: 3 | B11: 243CS0118 | C11: Abhiman Maurya | D11: 9 | E11: 8 | F11: 3 | G11: 6 | H11: 4 | I11: 6 | J11: 4 | K11: 1 | L11: =SUM(D11:K11) -> 41 | M11: =(L11/56)*100 -> 73.214286 | N11: =L11+'March 2025'!L11+'Feb 2025'!K11 -> 66 | O11: =N11/143 -> 0.46153846
A12: 4 | B12: 243CS0110 | C12: Abhishek Patidar | D12: 3 | E12: 0 | F12: 0 | G12: 0 | H12: 1 | I12: 1 | J12: 0 | K12: 0 | L12: =SUM(D12:K12) -> 5 | M12: =(L12/56)*100 -> 8.9285714 | N12: =L12+'March 2025'!L12+'Feb 2025'!K12 -> 5 | O12: =N12/143 -> 0.034965035
A13: 5 | B13: 243CS0073 | C13: Aditya Barsena | D13: 8 | E13: 7 | F13: 0 | G13: 0 | H13: 3 | I13: 7 | J13: 1 | K13: 0 | L13: =SUM(D13:K13) -> 26 | M13: =(L13/56)*100 -> 46.428571 | N13: =L13+'March 2025'!L13+'Feb 2025'!K13 -> 68 | O13: =N13/143 -> 0.47552448
A14: 6 | B14: 243CSD003 | C14: Aditya Dev Pandey | D14: 7 | E14: 6 | F14: 4 | G14: 4 | H14: 5 | I14: 7 | J14: 1 | K14: 1 | L14: =SUM(D14:K14) -> 35 | M14: =(L14/56)*100 -> 62.5 | N14: =L14+'March 2025'!L14+'Feb 2025'!K14 -> 46 | O14: =N14/143 -> 0.32167832
A15: 7 | B15: 243CS0053 | C15: Ankit Dabi | D15: 5 | E15: 3 | F15: 3 | G15: 2 | H15: 5 | I15: 5 | J15: 3 | K15: 2 | L15: =SUM(D15:K15) -> 28 | M15: =(L15/56)*100 -> 50 | N15: =L15+'March 2025'!L15+'Feb 2025'!K15 -> 60 | O15: =N15/143 -> 0.41958042
A16: 8 | B16: 243CS0026 | C16: Arman Chandravanshi | D16: 8 | E16: 6 | F16: 3 | G16: 0 | H16: 6 | I16: 5 | J16: 2 | K16: 0 | L16: =SUM(D16:K16) -> 30 | M16: =(L16/56)*100 -> 53.571429 | N16: =L16+'March 2025'!L16+'Feb 2025'!K16 -> 85 | O16: =N16/143 -> 0.59440559
A17: 9 | B17: 243CS0025 | C17: Ayush Chourey | D17: 9 | E17: 9 | F17: 5 | G17: 2 | H17: 6 | I17: 4 | J17: 4 | K17: 1 | L17: =SUM(D17:K17) -> 40 | M17: =(L17/56)*100 -> 71.428571 | N17: =L17+'March 2025'!L17+'Feb 2025'!K17 -> 64 | O17: =N17/143 -> 0.44755245
A18: 10 | B18: 243CS0004 | C18: Ayush Kumar Sinha | D18: 0 | E18: 0 | F18: 1 | G18: 0 | H18: 1 | I18: 1 | J18: 3 | K18: 0 | L18: =SUM(D18:K18) -> 6 | M18: =(L18/56)*100 -> 10.714286 | N18: =L18+'March 2025'!L18+'Feb 2025'!K18 -> 16 | O18: =N18/143 -> 0.11188811
A19: 11 | B19: 243CS0165 | C19: Bhumika Kale | D19: 5 | E19: 6 | F19: 1 | G19: 2 | H19: 5 | I19: 6 | J19: 1 | K19: 1 | L19: =SUM(D19:K19) -> 27 | M19: =(L19/56)*100 -> 48.214286 | N19: =L19+'March 2025'!L19+'Feb 2025'!K19 -> 66 | O19: =N19/143 -> 0.46153846
A20: 12 | B20: 243CS0047 | C20: Chandani Kose | D20: 9 | E20: 9 | F20: 6 | G20: 0 | H20: 6 | I20: 8 | J20: 3 | K20: 0 | L20: =SUM(D20:K20) -> 41 | M20: =(L20/56)*100 -> 73.214286 | N20: =L20+'March 2025'!L20+'Feb 2025'!K20 -> 94 | O20: =N20/143 -> 0.65734266
... A65: 57 | B65: 243CS0111 | C65: Vineeta Diwaniya | D65: 8 | E65: 9 | F65: 3 | G65: 2 | H65: 5 | I65: 7 | J65: 5 | K65: 1 | L65: =SUM(D65:K65) -> 40 | M65: =(L65/56)*100 -> 71.428571 | N65: =L65+'March 2025'!L65+'Feb 2025'!K65 -> 73 | O65: =N65/143 -> 0.51048951
A66: Faculty Name | D66: Ms Monika Singh | E66: Mr. Mukesh Sharma | F66: Ms. Fiona Lawrence | G66: Dr. Akash Agrawal | H66: Dr. Mamta Meena | I66: Mr. Rounak Bharadwaj | J66: Dr Shipra Ahuja | K66: Dr. Sonal John
A71: Ms.Fiona Lawrence TG, B.Tech. II Sem | E71: Dr.Mamta Meena HOD (CSE) | L71: Prof. (Dr.) Shailendra Singh Dean Engineering

Sheet Sheet1

Sheet assessment & attendance
A1: Oriental University, Indore
A2: Faculty of Computer Science & Engineering
A3: B. Tech(Plain) - A Section , II Semester Attendance: May 2025
A4: S.No. | B4: Enrolment No. | C4: Name of Student | D4: ENGINEERING MATHEMATICS-II | E4: FUNDAMENTALS OF ENGINEERING | F4: PROGRAMMING IN C | G4: DIGITAL SYSTEMS | H4: UNIVERSAL HUMAN VALUES | I4: ENGINEERING MATHEMATICS-II | J4: FUNDAMENTALS OF ENGINEERING | K4: PROGRAMMING IN C | L4: DIGITAL SYSTEMS | M4: UNIVERSAL HUMAN VALUES | N4: Total Class Feb+March+April | O4: Percentage Feb+March+April
N7: =SUM(D7:M7) -> 0 | O7: %
D8: MST-1 | I8: MST-2 | N8: 143
A9: 1 | B9: 2425CS8383 | C9: Aanchal Pandey | D9: ABS | E9: ABS | F9: ABS | G9: abs | H9: A | N9: 29 | O9: 0.2027972
A10: 2 | B10: 243CA0063 | C10: Aastha Mathankar | D10: 0 | E10: ABS | F10: 9 | G10: 4 | H10: A | N10: 51 | O10: 0.35664336
A11: 3 | B11: 243CS0118 | C11: Abhiman Maurya | D11: ABS | E11: 12 | F11: 14 | G11: 15 | H11: 18 | N11: 66 | O11: 0.46153846
A12: 4 | B12: 243CS0110 | C12: Abhishek Patidar | D12: ABS | E12: ABS | F12: ABS | G12: abs | H12: A | N12: 5 | O12: 0.034965035
A13: 5 | B13: 243CS0073 | C13: Aditya Barsena | D13: 1 | E13: 9 | F13: 6 | G13: 15 | H13: A | N13: 68 | O13: 0.47552448
A14: 6 | B14: 243CSD003 | C14: Aditya Dev Pandey | D14: 1 | E14: 12 | F14: 15 | G14: 13 | H14: 18 | N14: 46 | O14: 0.32167832
A15: 7 | B15: 243CS0053 | C15: Ankit Dabi | D15: ABS | E15: ABS | F15: ABS | G15: abs | H15: A | N15: 60 | O15: 0.41958042
A16: 8 | B16: 243CS0026 | C16: Arman Chandravanshi | D16: ABS | E16: ABS | F16: ABS | G16: abs | H16: A | N16: 85 | O16: 0.59440559
A17: 9 | B17: 243CS0025 | C17: Ayush Chourey | D17: ABS | E17: 6 | F17: 6 | G17: 0 | H17: 7 | N17: 64 | O17: 0.44755245
A18: 10 | B18: 243CS0004 | C18: Ayush Kumar Sinha | D18: ABS | E18: ABS | F18: ABS | G18: abs | H18: A | N18: 16 | O18: 0.11188811
A19: 11 | B19: 243CS0165 | C19: Bhumika Kale | D19: ABS | E19: ABS | F19: ABS | G19: abs | H19: A | N19: 66 | O19: 0.46153846
A20: 12 | B20: 243CS0047 | C20: Chandani Kose | D20: 12 | E20: 16 | F20: 7 | G20: 15 | H20: 18 | N20: 94 | O20: 0.65734266
A21: 13 | B21: 243CS0065 | C21: Daksh Mandiwal | D21: 2 | E21: 8 | F21: 7 | G21: 8 | H21: 3 | N21: 76 | O21: 0.53146853
A22: 14 | B22: 243CS0159 | C22: Dakshita Shukla | D22: 3 | E22: 6 | F22: 1 | G22: 6 | H22: 11 | N22: 59 | O22: 0.41258741
A23: 15 | B23: 243CS0034 | C23: Dhananjay Vishwakarma | D23: ABS | E23: ABS | F23: ABS | G23: abs | H23: A | N23: 0 | O23: 0
A24: 16 | B24: 243CS0045 | C24: Gautam Kumar Mishra | D24: ABS | E24: ABS | F24: ABS | G24: abs | H24: A | N24: 28 | O24: 0.1958042
A25: 17 | B25: 243CS0018 | C25: Gouri Rathod | D25: ABS | E25: 2 | F25: 0 | G25: 1 | H25: 0 | N25: 40 | O25: 0.27972028
A26: 18 | B26: 243CS0019 | C26: Gungun Kumari | D26: 4 | E26: 12 | F26: 5 | G26: 16 | H26: 3 | N26: 67 | O26: 0.46853147
A27: 19 | B27: 243CA0014 | C27: Hariom Jadoun | D27: ABS | E27: ABS | F27: ABS | G27: abs | H27: A | N27: 56 | O27: 0.39160839
A28: 20 | B28: 243CSA067 | C28: Hariom Parmar | D28: ABS | E28: ABS | F28: ABS | G28: abs | H28: A | N28: 65 | O28: 0.45454545
A29: 21 | B29: 243CS0137 | C29: Kailash Nandeda | D29: ABS | E29: 10 | F29: 7 | G29: 11 | H29: 16 | N29: 66 | O29: 0.46153846
A30: 22 | B30: 243CS0006 | C30: Kartik Maurya | D30: 3 | E30: 2 | F30: 9 | G30: 13 | H30: A | N30: 60 | O30: 0.41958042
A31: 23 | B31: 243CS0079 | C31: Kore Shiva Kumar | D31: ABS | E31: ABS | F31: ABS | G31: abs | H31: A | N31: 0 | O31: 0
A32: 24 | B32: 243CS0116 | C32: Kunal Kumawat | D32: 6 | E32: 16 | F32: 10 | G32: 14 | H32: 12 | N32: 94 | O32: 0.65734266
A33: 25 | B33: 243CS0141 | C33: Kushagra Purohit | D33: ABS | E33: ABS | F33: ABS | G33: abs | H33: A | N33: 10 | O33: 0.06993007
A34: 26 | B34: 243CSA160 | C34: Lakshay | D34: 0 | E34: ABS | F34: ABS | G34: abs | H34: 5 | N34: 35 | O34: 0.24475524
A35: 27 | B35: 243CS0154 | C35: Larvia Nankani | D35: 8 | E35: 6 | F35: 11 | G35: 12 | H35: 19 | N35: 74 | O35: 0.51748252
A36: 28 | B36: 243CS0105 | C36: Manish Satpute | D36: ABS | E36: 3 | F36: 3 | G36: abs | H36: A | N36: 57 | O36: 0.3986014
A37: 29 | B37: 243CS0069 | C37: Manoj Chouhan | D37: 0 | E37: 4 | F37: 1 | G37: 4 | H37: A | N37: 46 | O37: 0.32167832
A38: 30 | B38: 243CS0043 | C38: Minal Ratnawat | D38: 15 | E38: 5 | F38: 18 | G38: 13 | H38: 18 | N38: 55 | O38: 0.38461538
A39: 31 | B39: 243CS0054 | C39: Mishra Shrayansh Mukesh | D39: 12 | E39: 5 | F39: ABS | G39: abs | H39: A | N39: 57 | O39: 0.3986014
A40: 32 | B40: 243CS0075 | C40: Muskan Pawar | D40: 3 | E40: 11 | F40: 9 | G40: 10 | H40: 16 | N40: 60 | O40: 0.41958042
A41: 33 | B41: 243CSE021 | C41: Narendra | D41: ABS | E41: ABS | F41: ABS | G41: abs | H41: A | N41: 24 | O41: 0.16783217
A42: 34 | B42: 243CS0143 | C42: Neha Rathore | D42: 7 | E42: ABS | F42: ABS | G42: abs | H42: A | N42: 43 | O42: 0.3006993
...
